Workbook

Sheet Apps
O1: 1000 | Q1: Weight | R1: 1000 | S1: 10 | T1: 10 | U1: 10 | V1: 5 | W1: 5 | X1: 5 | Y1: 3 | Z1: 1 | AA1: 1 | AB1: 1
A3: =J3&";"&K3&";"&B3&";"&C3&";"&D3&";"&E3&";"&F3&";"&G3&";"&H3&";"&I3 -> App;User Group;1;2;3;4;5;6;7;8 | B3: 1 | C3: 2 | D3: 3 | E3: 4 | F3: 5 | G3: 6 | H3: 7 | I3: 8 | J3: App | K3: User Group | L3: EUR (manual) | M3: EUR (analysis) | N3: EUR (cloc) | O3: EUR | P3: EUR/Unit | Q3: Units | R3: base | S3: mail | T3: product | U3: account | V3: website | W3: calendar,contact,hr,sale_management | X3: apps in use | Y3: apps | Z3: odoo | AA3: OCA | AB3: Other
A4: =J4&";"&K4&";"&B4&";"&C4&";"&D4&";"&E4&";"&F4&";"&G4&";"&H4&";"&I4 -> account;base.group_user;24;48;72;96;120;144;168;192 | B4: =$P4*MIN($Q4,B$3) -> 24 | C4: =$P4*MIN($Q4,C$3) -> 48 | D4: =$P4*MIN($Q4,D$3) -> 72 | E4: =$P4*MIN($Q4,E$3) -> 96 | F4: =$P4*MIN($Q4,F$3) -> 120 | G4: =$P4*MIN($Q4,G$3) -> 144 | H4: =$P4*MIN($Q4,H$3) -> 168 | I4: =$P4*MIN($Q4,I$3) -> 192 | J4: account | K4: base.group_user | M4: =INDEX('Pivot Analysis'!A:B,MATCH(J4,'Pivot Analysis'!B:B,0),1) -> 240 | N4: =INDEX(Cloc!E:F,MATCH(J4,Cloc!F:F,0),1) -> 2988.36 | O4: =IFERROR(IFERROR(IF(L4<>"",L4,M4),N4),$O$1) -> 240 | P4: =O4/Q4 -> 24 | Q4: =MAX(1,SUMPRODUCT($R$1:$AD$1,R4:AD4)) -> 10 | U4: 1 | X4: =IF(SUM(R4:W4)=0,VLOOKUP(J4,#REF!,1,0),"") | Y4: =IF(SUM(R4:X4)>0,"",VLOOKUP(J4,'Apps-from-odoo'!A:A,1,0))
A5: =J5&";"&K5&";"&B5&";"&C5&";"&D5&";"&E5&";"&F5&";"&G5&";"&H5&";"&I5 -> account_audit_trail;base.group_user;0;0;0;0;0;0;0;0 | B5: =$P5*MIN($Q5,B$3) -> 0 | C5: =$P5*MIN($Q5,C$3) -> 0 | D5: =$P5*MIN($Q5,D$3) -> 0 | E5: =$P5*MIN($Q5,E$3) -> 0 | F5: =$P5*MIN($Q5,F$3) -> 0 | G5: =$P5*MIN($Q5,G$3) -> 0 | H5: =$P5*MIN($Q5,H$3) -> 0 | I5: =$P5*MIN($Q5,I$3) -> 0 | J5: account_audit_trail | K5: base.group_user | M5: =INDEX('Pivot Analysis'!A:B,MATCH(J5,'Pivot Analysis'!B:B,0),1) -> 0 | N5: =INDEX(Cloc!E:F,MATCH(J5,Cloc!F:F,0),1) -> #N/A | O5: =IFERROR(IFERROR(IF(L5<>"",L5,M5),N5),$O$1) -> 0 | P5: =O5/Q5 -> 0 | Q5: =MAX(1,SUMPRODUCT($R$1:$AD$1,R5:AD5)) -> 1
A6: =J6&";"&K6&";"&B6&";"&C6&";"&D6&";"&E6&";"&F6&";"&G6&";"&H6&";"&I6 -> account_check_printing;base.group_user;7,5;7,5;7,5;7,5;7,5;7,5;7,5;7,5 | B6: =$P6*MIN($Q6,B$3) -> 7.5 | C6: =$P6*MIN($Q6,C$3) -> 7.5 | D6: =$P6*MIN($Q6,D$3) -> 7.5 | E6: =$P6*MIN($Q6,E$3) -> 7.5 | F6: =$P6*MIN($Q6,F$3) -> 7.5 | G6: =$P6*MIN($Q6,G$3) -> 7.5 | H6: =$P6*MIN($Q6,H$3) -> 7.5 | I6: =$P6*MIN($Q6,I$3) -> 7.5 | J6: account_check_printing | K6: base.group_user | M6: =INDEX('Pivot Analysis'!A:B,MATCH(J6,'Pivot Analysis'!B:B,0),1) -> 7.5 | N6: =INDEX(Cloc!E:F,MATCH(J6,Cloc!F:F,0),1) -> #N/A | O6: =IFERROR(IFERROR(IF(L6<>"",L6,M6),N6),$O$1) -> 7.5 | P6: =O6/Q6 -> 7.5 | Q6: =MAX(1,SUMPRODUCT($R$1:$AD$1,R6:AD6)) -> 1
A7: =J7&";"&K7&";"&B7&";"&C7&";"&D7&";"&E7&";"&F7&";"&G7&";"&H7&";"&I7 -> account_debit_note;base.group_user;34,5;34,5;34,5;34,5;34,5;34,5;34,5;34,5 | B7: =$P7*MIN($Q7,B$3) -> 34.5 | C7: =$P7*MIN($Q7,C$3) -> 34.5 | D7: =$P7*MIN($Q7,D$3) -> 34.5 | E7: =$P7*MIN($Q7,E$3) -> 34.5 | F7: =$P7*MIN($Q7,F$3) -> 34.5 | G7: =$P7*MIN($Q7,G$3) -> 34.5 | H7: =$P7*MIN($Q7,H$3) -> 34.5 | I7: =$P7*MIN($Q7,I$3) -> 34.5 | J7: account_debit_note | K7: base.group_user | M7: =INDEX('Pivot Analysis'!A:B,MATCH(J7,'Pivot Analysis'!B:B,0),1) -> 34.5 | N7: =INDEX(Cloc!E:F,MATCH(J7,Cloc!F:F,0),1) -> #N/A | O7: =IFERROR(IFERROR(IF(L7<>"",L7,M7),N7),$O$1) -> 34.5 | P7: =O7/Q7 -> 34.5 | Q7: =MAX(1,SUMPRODUCT($R$1:$AD$1,R7:AD7)) -> 1
A8: =J8&";"&K8&";"&B8&";"&C8&";"&D8&";"&E8&";"&F8&";"&G8&";"&H8&";"&I8 -> account_edi;base.group_user;0;0;0;0;0;0;0;0 | B8: =$P8*MIN($Q8,B$3) -> 0 | C8: =$P8*MIN($Q8,C$3) -> 0 | D8: =$P8*MIN($Q8,D$3) -> 0 | E8: =$P8*MIN($Q8,E$3) -> 0 | F8: =$P8*MIN($Q8,F$3) -> 0 | G8: =$P8*MIN($Q8,G$3) -> 0 | H8: =$P8*MIN($Q8,H$3) -> 0 | I8: =$P8*MIN($Q8,I$3) -> 0 | J8: account_edi | K8: base.group_user | M8: =INDEX('Pivot Analysis'!A:B,MATCH(J8,'Pivot Analysis'!B:B,0),1) -> 0 | N8: =INDEX(Cloc!E:F,MATCH(J8,Cloc!F:F,0),1) -> #N/A | O8: =IFERROR(IFERROR(IF(L8<>"",L8,M8),N8),$O$1) -> 0 | P8: =O8/Q8 -> 0 | Q8: =MAX(1,SUMPRODUCT($R$1:$AD$1,R8:AD8)) -> 1
A9: =J9&";"&K9&";"&B9&";"&C9&";"&D9&";"&E9&";"&F9&";"&G9&";"&H9&";"&I9 -> account_edi_proxy_client;base.group_user;81;81;81;81;81;81;81;81 | B9: =$P9*MIN($Q9,B$3) -> 81 | C9: =$P9*MIN($Q9,C$3) -> 81 | D9: =$P9*MIN($Q9,D$3) -> 81 | E9: =$P9*MIN($Q9,E$3) -> 81 | F9: =$P9*MIN($Q9,F$3) -> 81 | G9: =$P9*MIN($Q9,G$3) -> 81 | H9: =$P9*MIN($Q9,H$3) -> 81 | I9: =$P9*MIN($Q9,I$3) -> 81 | J9: account_edi_proxy_client | K9: base.group_user | M9: =INDEX('Pivot Analysis'!A:B,MATCH(J9,'Pivot Analysis'!B:B,0),1) -> 81 | N9: =INDEX(Cloc!E:F,MATCH(J9,Cloc!F:F,0),1) -> #N/A | O9: =IFERROR(IFERROR(IF(L9<>"",L9,M9),N9),$O$1) -> 81 | P9: =O9/Q9 -> 81 | Q9: =MAX(1,SUMPRODUCT($R$1:$AD$1,R9:AD9)) -> 1
A10: =J10&";"&K10&";"&B10&";"&C10&";"&D10&";"&E10&";"&F10&";"&G10&";"&H10&";"&I10 -> account_edi_ubl_cii;base.group_user;1,23;2,46;3,69;4,92;6,15;7,38;8,61;9,84 | B10: =$P10*MIN($Q10,B$3) -> 1.23 | C10: =$P10*MIN($Q10,C$3) -> 2.46 | D10: =$P10*MIN($Q10,D$3) -> 3.69 | E10: =$P10*MIN($Q10,E$3) -> 4.92 | F10: =$P10*MIN($Q10,F$3) -> 6.15 | G10: =$P10*MIN($Q10,G$3) -> 7.38 | H10: =$P10*MIN($Q10,H$3) -> 8.61 | I10: =$P10*MIN($Q10,I$3) -> 9.84 | J10: account_edi_ubl_cii | K10: base.group_user | M10: =INDEX('Pivot Analysis'!A:B,MATCH(J10,'Pivot Analysis'!B:B,0),1) -> 12.3 | N10: =INDEX(Cloc!E:F,MATCH(J10,Cloc!F:F,0),1) -> 284.1 | O10: =IFERROR(IFERROR(IF(L10<>"",L10,M10),N10),$O$1) -> 12.3 | P10: =O10/Q10 -> 1.23 | Q10: =MAX(1,SUMPRODUCT($R$1:$AD$1,R10:AD10)) -> 10 | U10: 1 | X10: =IF(SUM(R10:W10)=0,VLOOKUP(J10,#REF!,1,0),"") | Y10: =IF(SUM(R10:X10)>0,"",VLOOKUP(J10,'Apps-from-odoo'!A:A,1,0))
A11: =J11&";"&K11&";"&B11&";"&C11&";"&D11&";"&E11&";"&F11&";"&G11&";"&H11&";"&I11 -> account_edi_ubl_cii_tax_extension;base.group_user;0;0;0;0;0;0;0;0 | B11: =$P11*MIN($Q11,B$3) -> 0 | C11: =$P11*MIN($Q11,C$3) -> 0 | D11: =$P11*MIN($Q11,D$3) -> 0 | E11: =$P11*MIN($Q11,E$3) -> 0 | F11: =$P11*MIN($Q11,F$3) -> 0 | G11: =$P11*MIN($Q11,G$3) -> 0 | H11: =$P11*MIN($Q11,H$3) -> 0 | I11: =$P11*MIN($Q11,I$3) -> 0 | J11: account_edi_ubl_cii_tax_extension | K11: base.group_user | M11: =INDEX('Pivot Analysis'!A:B,MATCH(J11,'Pivot Analysis'!B:B,0),1) -> 0 | N11: =INDEX(Cloc!E:F,MATCH(J11,Cloc!F:F,0),1) -> #N/A | O11: =IFERROR(IFERROR(IF(L11<>"",L11,M11),N11),$O$1) -> 0 | P11: =O11/Q11 -> 0 | Q11: =MAX(1,SUMPRODUCT($R$1:$AD$1,R11:AD11)) -> 1
A12: =J12&";"&K12&";"&B12&";"&C12&";"&D12&";"&E12&";"&F12&";"&G12&";"&H12&";"&I12 -> account_fleet;base.group_user;1,5;3;4,5;6;7,5;7,5;7,5;7,5 | B12: =$P12*MIN($Q12,B$3) -> 1.5 | C12: =$P12*MIN($Q12,C$3) -> 3 | D12: =$P12*MIN($Q12,D$3) -> 4.5 | E12: =$P12*MIN($Q12,E$3) -> 6 | F12: =$P12*MIN($Q12,F$3) -> 7.5 | G12: =$P12*MIN($Q12,G$3) -> 7.5 | H12: =$P12*MIN($Q12,H$3) -> 7.5 | I12: =$P12*MIN($Q12,I$3) -> 7.5 | J12: account_fleet | K12: base.group_user | M12: =INDEX('Pivot Analysis'!A:B,MATCH(J12,'Pivot Analysis'!B:B,0),1) -> 7.5 | N12: =INDEX(Cloc!E:F,MATCH(J12,Cloc!F:F,0),1) -> 17.28 | O12: =IFERROR(IFERROR(IF(L12<>"",L12,M12),N12),$O$1) -> 7.5 | P12: =O12/Q12 -> 1.5 | Q12: =MAX(1,SUMPRODUCT($R$1:$AD$1,R12:AD12)) -> 5 | X12: 1 | Y12: =IF(SUM(R12:X12)>0,"",VLOOKUP(J12,'Apps-from-odoo'!A:A,1,0))
A13: =J13&";"&K13&";"&B13&";"&C13&";"&D13&";"&E13&";"&F13&";"&G13&";"&H13&";"&I13 -> account_lock;base.group_user;30;30;30;30;30;30;30;30 | B13: =$P13*MIN($Q13,B$3) -> 30 | C13: =$P13*MIN($Q13,C$3) -> 30 | D13: =$P13*MIN($Q13,D$3) -> 30 | E13: =$P13*MIN($Q13,E$3) -> 30 | F13: =$P13*MIN($Q13,F$3) -> 30 | G13: =$P13*MIN($Q13,G$3) -> 30 | H13: =$P13*MIN($Q13,H$3) -> 30 | I13: =$P13*MIN($Q13,I$3) -> 30 | J13: account_lock | K13: base.group_user | M13: =INDEX('Pivot Analysis'!A:B,MATCH(J13,'Pivot Analysis'!B:B,0),1) -> 30 | N13: =INDEX(Cloc!E:F,MATCH(J13,Cloc!F:F,0),1) -> #N/A | O13: =IFERROR(IFERROR(IF(L13<>"",L13,M13),N13),$O$1) -> 30 | P13: =O13/Q13 -> 30 | Q13: =MAX(1,SUMPRODUCT($R$1:$AD$1,R13:AD13)) -> 1
A14: =J14&";"&K14&";"&B14&";"&C14&";"&D14&";"&E14&";"&F14&";"&G14&";"&H14&";"&I14 -> account_payment;base.group_user;0,33;0,66;0,99;1,32;1,65;1,98;2,31;2,64 | B14: =$P14*MIN($Q14,B$3) -> 0.33 | C14: =$P14*MIN($Q14,C$3) -> 0.66 | D14: =$P14*MIN($Q14,D$3) -> 0.99 | E14: =$P14*MIN($Q14,E$3) -> 1.32 | F14: =$P14*MIN($Q14,F$3) -> 1.65 | G14: =$P14*MIN($Q14,G$3) -> 1.98 | H14: =$P14*MIN($Q14,H$3) -> 2.31 | I14: =$P14*MIN($Q14,I$3) -> 2.64 | J14: account_payment | K14: base.group_user | M14: =INDEX('Pivot Analysis'!A:B,MATCH(J14,'Pivot Analysis'!B:B,0),1) -> 3.3 | N14: =INDEX(Cloc!E:F,MATCH(J14,Cloc!F:F,0),1) -> 140.94 | O14: =IFERROR(IFERROR(IF(L14<>"",L14,M14),N14),$O$1) -> 3.3 | P14: =O14/Q14 -> 0.33 | Q14: =MAX(1,SUMPRODUCT($R$1:$AD$1,R14:AD14)) -> 10 | U14: 1 | X14: =IF(SUM(R14:W14)=0,VLOOKUP(J14,#REF!,1,0),"") | Y14: =IF(SUM(R14:X14)>0,"",VLOOKUP(J14,'Apps-from-odoo'!A:A,1,0))
A15: =J15&";"&K15&";"&B15&";"&C15&";"&D15&";"&E15&";"&F15&";"&G15&";"&H15&";"&I15 -> account_payment_invoice_online_payment_patch;base.group_user;0;0;0;0;0;0;0;0 | B15: =$P15*MIN($Q15,B$3) -> 0 | C15: =$P15*MIN($Q15,C$3) -> 0 | D15: =$P15*MIN($Q15,D$3) -> 0 | E15: =$P15*MIN($Q15,E$3) -> 0 | F15: =$P15*MIN($Q15,F$3) -> 0 | G15: =$P15*MIN($Q15,G$3) -> 0 | H15: =$P15*MIN($Q15,H$3) -> 0 | I15: =$P15*MIN($Q15,I$3) -> 0 | J15: account_payment_invoice_online_payment_patch | K15: base.group_user | M15: =INDEX('Pivot Analysis'!A:B,MATCH(J15,'Pivot Analysis'!B:B,0),1) -> 0 | N15: =INDEX(Cloc!E:F,MATCH(J15,Cloc!F:F,0),1) -> #N/A | O15: =IFERROR(IFERROR(IF(L15<>"",L15,M15),N15),$O$1) -> 0 | P15: =O15/Q15 -> 0 | Q15: =MAX(1,SUMPRODUCT($R$1:$AD$1,R15:AD15)) -> 1
A16: =J16&";"&K16&";"&B16&";"&C16&";"&D16&";"&E16&";"&F16&";"&G16&";"&H16&";"&I16 -> account_payment_term;base.group_user;0;0;0;0;0;0;0;0 | B16: =$P16*MIN($Q16,B$3) -> 0 | C16: =$P16*MIN($Q16,C$3) -> 0 | D16: =$P16*MIN($Q16,D$3) -> 0 | E16: =$P16*MIN($Q16,E$3) -> 0 | F16: =$P16*MIN($Q16,F$3) -> 0 | G16: =$P16*MIN($Q16,G$3) -> 0 | H16: =$P16*MIN($Q16,H$3) -> 0 | I16: =$P16*MIN($Q16,I$3) -> 0 | J16: account_payment_term | K16: base.group_user | M16: =INDEX('Pivot Analysis'!A:B,MATCH(J16,'Pivot Analysis'!B:B,0),1) -> 0 | N16: =INDEX(Cloc!E:F,MATCH(J16,Cloc!F:F,0),1) -> #N/A | O16: =IFERROR(IFERROR(IF(L16<>"",L16,M16),N16),$O$1) -> 0 | P16: =O16/Q16 -> 0 | Q16: =MAX(1,SUMPRODUCT($R$1:$AD$1,R16:AD16)) -> 1
A17: =J17&";"&K17&";"&B17&";"&C17&";"&D17&";"&E17&";"&F17&";"&G17&";"&H17&";"&I17 -> account_peppol;base.group_user;258;258;258;258;258;258;258;258 | B17: =$P17*MIN($Q17,B$3) -> 258 | C17: =$P17*MIN($Q17,C$3) -> 258 | D17: =$P17*MIN($Q17,D$3) -> 258 | E17: =$P17*MIN($Q17,E$3) -> 258 | F17: =$P17*MIN($Q17,F$3) -> 258 | G17: =$P17*MIN($Q17,G$3) -> 258 | H17: =$P17*MIN($Q17,H$3) -> 258 | I17: =$P17*MIN($Q17,I$3) -> 258 | J17: account_peppol | K17: base.group_user | M17: =INDEX('Pivot Analysis'!A:B,MATCH(J17,'Pivot Analysis'!B:B,0),1) -> 258 | N17: =INDEX(Cloc!E:F,MATCH(J17,Cloc!F:F,0),1) -> #N/A | O17: =IFERROR(IFERROR(IF(L17<>"",L17,M17),N17),$O$1) -> 258 | P17: =O17/Q17 -> 258 | Q17: =MAX(1,SUMPRODUCT($R$1:$AD$1,R17:AD17)) -> 1
A18: =J18&";"&K18&";"&B18&";"&C18&";"&D18&";"&E18&";"&F18&";"&G18&";"&H18&";"&I18 -> account_qr_code_emv;base.group_user;45;45;45;45;45;45;45;45 | B18: =$P18*MIN($Q18,B$3) -> 45 | C18: =$P18*MIN($Q18,C$3) -> 45 | D18: =$P18*MIN($Q18,D$3) -> 45 | E18: =$P18*MIN($Q18,E$3) -> 45 | F18: =$P18*MIN($Q18,F$3) -> 45 | G18: =$P18*MIN($Q18,G$3) -> 45 | H18: =$P18*MIN($Q18,H$3) -> 45 | I18: =$P18*MIN($Q18,I$3) -> 45 | J18: account_qr_code_emv | K18: base.group_user | M18: =INDEX('Pivot Analysis'!A:B,MATCH(J18,'Pivot Analysis'!B:B,0),1) -> 45 | N18: =INDEX(Cloc!E:F,MATCH(J18,Cloc!F:F,0),1) -> #N/A | O18: =IFERROR(IFERROR(IF(L18<>"",L18,M18),N18),$O$1) -> 45 | P18: =O18/Q18 -> 45 | Q18: =MAX(1,SUMPRODUCT($R$1:$AD$1,R18:AD18)) -> 1
A19: =J19&";"&K19&";"&B19&";"&C19&";"&D19&";"&E19&";"&F19&";"&G19&";"&H19&";"&I19 -> account_qr_code_sepa;base.group_user;3;3;3;3;3;3;3;3 | B19: =$P19*MIN($Q19,B$3) -> 3 | C19: =$P19*MIN($Q19,C$3) -> 3 | D19: =$P19*MIN($Q19,D$3) -> 3 | E19: =$P19*MIN($Q19,E$3) -> 3 | F19: =$P19*MIN($Q19,F$3) -> 3 | G19: =$P19*MIN($Q19,G$3) -> 3 | H19: =$P19*MIN($Q19,H$3) -> 3 | I19: =$P19*MIN($Q19,I$3) -> 3 | J19: account_qr_code_sepa | K19: base.group_user | M19: =INDEX('Pivot Analysis'!A:B,MATCH(J19,'Pivot Analysis'!B:B,0),1) -> 3 | N19: =INDEX(Cloc!E:F,MATCH(J19,Cloc!F:F,0),1) -> #N/A | O19: =IFERROR(IFERROR(IF(L19<>"",L19,M19),N19),$O$1) -> 3 | P19: =O19/Q19 -> 3 | Q19: =MAX(1,SUMPRODUCT($R$1:$AD$1,R19:AD19)) -> 1
A20: =J20&";"&K20&";"&B20&";"&C20&";"&D20&";"&E20&";"&F20&";"&G20&";"&H20&";"&I20 -> account_sequence;base.group_user;0;0;0;0;0;0;0;0 | B20: =$P20*MIN($Q20,B$3) -> 0 | C20: =$P20*MIN($Q20,C$3) -> 0 | D20: =$P20*MIN($Q20,D$3) -> 0 | E20: =$P20*MIN($Q20,E$3) -> 0 | F20: =$P20*MIN($Q20,F$3) -> 0 | G20: =$P20*MIN($Q20,G$3) -> 0 | H20: =$P20*MIN($Q20,H$3) -> 0 | I20: =$P20*MIN($Q20,I$3) -> 0 | J20: account_sequence | K20: base.group_user | M20: =INDEX('Pivot Analysis'!A:B,MATCH(J20,'Pivot Analysis'!B:B,0),1) -> 0 | N20: =INDEX(Cloc!E:F,MATCH(J20,Cloc!F:F,0),1) -> #N/A | O20: =IFERROR(IFERROR(IF(L20<>"",L20,M20),N20),$O$1) -> 0 | P20: =O20/Q20 -> 0 | Q20: =MAX(1,SUMPRODUCT($R$1:$AD$1,R20:AD20)) -> 1
A21: =J21&";"&K21&";"&B21&";"&C21&";"&D21&";"&E21&";"&F21&";"&G21&";"&H21&";"&I21 -> account_tax_python;base.group_user;82,5;82,5;82,5;82,5;82,5;82,5;82,5;82,5 | B21: =$P21*MIN($Q21,B$3) -> 82.5 | C21: =$P21*MIN($Q21,C$3) -> 82.5 | D21: =$P21*MIN($Q21,D$3) -> 82.5 | E21: =$P21*MIN($Q21,E$3) -> 82.5 | F21: =$P21*MIN($Q21,F$3) -> 82.5 | G21: =$P21*MIN($Q21,G$3) -> 82.5 | H21: =$P21*MIN($Q21,H$3) -> 82.5 | I21: =$P21*MIN($Q21,I$3) -> 82.5 | J21: account_tax_python | K21: base.group_user | M21: =INDEX('Pivot Analysis'!A:B,MATCH(J21,'Pivot Analysis'!B:B,0),1) -> 82.5 | N21: =INDEX(Cloc!E:F,MATCH(J21,Cloc!F:F,0),1) -> #N/A | O21: =IFERROR(IFERROR(IF(L21<>"",L21,M21),N21),$O$1) -> 82.5 | P21: =O21/Q21 -> 82.5 | Q21: =MAX(1,SUMPRODUCT($R$1:$AD$1,R21:AD21)) -> 1
A22: =J22&";"&K22&";"&B22&";"&C22&";"&D22&";"&E22&";"&F22&";"&G22&";"&H22&";"&I22 -> account_test;base.group_user;33;33;33;33;33;33;33;33 | B22: =$P22*MIN($Q22,B$3) -> 33 | C22: =$P22*MIN($Q22,C$3) -> 33 | D22: =$P22*MIN($Q22,D$3) -> 33 | E22: =$P22*MIN($Q22,E$3) -> 33 | F22: =$P22*MIN($Q22,F$3) -> 33 | G22: =$P22*MIN($Q22,G$3) -> 33 | H22: =$P22*MIN($Q22,H$3) -> 33 | I22: =$P22*MIN($Q22,I$3) -> 33 | J22: account_test | K22: base.group_user | M22: =INDEX('Pivot Analysis'!A:B,MATCH(J22,'Pivot Analysis'!B:B,0),1) -> 33 | N22: =INDEX(Cloc!E:F,MATCH(J22,Cloc!F:F,0),1) -> #N/A | O22: =IFERROR(IFERROR(IF(L22<>"",L22,M22),N22),$O$1) -> 33 | P22: =O22/Q22 -> 33 | Q22: =MAX(1,SUMPRODUCT($R$1:$AD$1,R22:AD22)) -> 1
A23: =J23&";"&K23&";"&B23&";"&C23&";"&D23&";"&E23&";"&F23&";"&G23&";"&H23&";"&I23 -> account_update_tax_tags;base.group_user;0;0;0;0;0;0;0;0 | B23: =$P23*MIN($Q23,B$3) -> 0 | C23: =$P23*MIN($Q23,C$3) -> 0 | D23: =$P23*MIN($Q23,D$3) -> 0 | E23: =$P23*MIN($Q23,E$3) -> 0 | F23: =$P23*MIN($Q23,F$3) -> 0 | G23: =$P23*MIN($Q23,G$3) -> 0 | H23: =$P23*MIN($Q23,H$3) -> 0 | I23: =$P23*MIN($Q23,I$3) -> 0 | J23: account_update_tax_tags | K23: base.group_user | M23: =INDEX('Pivot Analysis'!A:B,MATCH(J23,'Pivot Analysis'!B:B,0),1) -> 0 | N23: =INDEX(Cloc!E:F,MATCH(J23,Cloc!F:F,0),1) -> #N/A | O23: =IFERROR(IFERROR(IF(L23<>"",L23,M23),N23),$O$1) -> 0 | P23: =O23/Q23 -> 0 | Q23: =MAX(1,SUMPRODUCT($R$1:$AD$1,R23:AD23)) -> 1
A24: =J24&";"&K24&";"&B24&";"&C24&";"&D24&";"&E24&";"&F24&";"&G24&";"&H24&";"&I24 -> accountant;base.group_user;1000;1000;1000;1000;1000;1000;1000;1000 | B24: =$P24*MIN($Q24,B$3) -> 1000 | C24: =$P24*MIN($Q24,C$3) -> 1000 | D24: =$P24*MIN($Q24,D$3) -> 1000 | E24: =$P24*MIN($Q24,E$3) -> 1000 | F24: =$P24*MIN($Q24,F$3) -> 1000 | G24: =$P24*MIN($Q24,G$3) -> 1000 | H24: =$P24*MIN($Q24,H$3) -> 1000 | I24: =$P24*MIN($Q24,I$3) -> 1000 | J24: accountant | K24: base.group_user | M24: =INDEX('Pivot Analysis'!A:B,MATCH(J24,'Pivot Analysis'!B:B,0),1) -> #N/A | N24: =INDEX(Cloc!E:F,MATCH(J24,Cloc!F:F,0),1) -> #N/A | O24: =IFERROR(IFERROR(IF(L24<>"",L24,M24),N24),$O$1) -> 1000 | P24: =O24/Q24 -> 1000 | Q24: =MAX(1,SUMPRODUCT($R$1:$AD$1,R24:AD24)) -> 1 | Z24: 1
A25: =J25&";"&K25&";"&B25&";"&C25&";"&D25&";"&E25&";"&F25&";"&G25&";"&H25&";"&I25 -> analytic;base.group_user;0;0;0;0;0;0;0;0 | B25: =$P25*MIN($Q25,B$3) -> 0 | C25: =$P25*MIN($Q25,C$3) -> 0 | D25: =$P25*MIN($Q25,D$3) -> 0 | E25: =$P25*MIN($Q25,E$3) -> 0 | F25: =$P25*MIN($Q25,F$3) -> 0 | G25: =$P25*MIN($Q25,G$3) -> 0 | H25: =$P25*MIN($Q25,H$3) -> 0 | I25: =$P25*MIN($Q25,I$3) -> 0 | J25: analytic | K25: base.group_user | M25: =INDEX('Pivot Analysis'!A:B,MATCH(J25,'Pivot Analysis'!B:B,0),1) -> 0 | N25: =INDEX(Cloc!E:F,MATCH(J25,Cloc!F:F,0),1) -> 150 | O25: =IFERROR(IFERROR(IF(L25<>"",L25,M25),N25),$O$1) -> 0 | P25: =O25/Q25 -> 0 | Q25: =MAX(1,SUMPRODUCT($R$1:$AD$1,R25:AD25)) -> 10 | U25: 1 | X25: =IF(SUM(R25:W25)=0,VLOOKUP(J25,#REF!,1,0),"") | Y25: =IF(SUM(R25:X25)>0,"",VLOOKUP(J25,'Apps-from-odoo'!A:A,1,0))
A26: =J26&";"&K26&";"&B26&";"&C26&";"&D26&";"&E26&";"&F26&";"&G26&";"&H26&";"&I26 -> association;base.group_user;0;0;0;0;0;0;0;0 | B26: =$P26*MIN($Q26,B$3) -> 0 | C26: =$P26*MIN($Q26,C$3) -> 0 | D26: =$P26*MIN($Q26,D$3) -> 0 | E26: =$P26*MIN($Q26,E$3) -> 0 | F26: =$P26*MIN($Q26,F$3) -> 0 | G26: =$P26*MIN($Q26,G$3) -> 0 | H26: =$P26*MIN($Q26,H$3) -> 0 | I26: =$P26*MIN($Q26,I$3) -> 0 | J26: association | K26: base.group_user | M26: =INDEX('Pivot Analysis'!A:B,MATCH(J26,'Pivot Analysis'!B:B,0),1) -> 0 | N26: =INDEX(Cloc!E:F,MATCH(J26,Cloc!F:F,0),1) -> #N/A | O26: =IFERROR(IFERROR(IF(L26<>"",L26,M26),N26),$O$1) -> 0 | P26: =O26/Q26 -> 0 | Q26: =MAX(1,SUMPRODUCT($R$1:$AD$1,R26:AD26)) -> 1
A27: =J27&";"&K27&";"&B27&";"&C27&";"&D27&";"&E27&";"&F27&";"&G27&";"&H27&";"&I27 -> attachment_indexation;base.group_user;1;2;3;3;3;3;3;3 | B27: =$P27*MIN($Q27,B$3) -> 1 | C27: =$P27*MIN($Q27,C$3) -> 2 | D27: =$P27*MIN($Q27,D$3) -> 3 | E27: =$P27*MIN($Q27,E$3) -> 3 | F27: =$P27*MIN($Q27,F$3) -> 3 | G27: =$P27*MIN($Q27,G$3) -> 3 | H27: =$P27*MIN($Q27,H$3) -> 3 | I27: =$P27*MIN($Q27,I$3) -> 3 | J27: attachment_indexation | K27: base.group_user | M27: =INDEX('Pivot Analysis'!A:B,MATCH(J27,'Pivot Analysis'!B:B,0),1) -> 3 | N27: =INDEX(Cloc!E:F,MATCH(J27,Cloc!F:F,0),1) -> 9.3 | O27: =IFERROR(IFERROR(IF(L27<>"",L27,M27),N27),$O$1) -> 3 | P27: =O27/Q27 -> 1 | Q27: =MAX(1,SUMPRODUCT($R$1:$AD$1,R27:AD27)) -> 3 | Y27: 1
A28: =J28&";"&K28&";"&B28&";"&C28&";"&D28&";"&E28&";"&F28&";"&G28&";"&H28&";"&I28 -> auth_ldap;base.group_user;0;0;0;0;0;0;0;0 | B28: =$P28*MIN($Q28,B$3) -> 0 | C28: =$P28*MIN($Q28,C$3) -> 0 | D28: =$P28*MIN($Q28,D$3) -> 0 | E28: =$P28*MIN($Q28,E$3) -> 0 | F28: =$P28*MIN($Q28,F$3) -> 0 | G28: =$P28*MIN($Q28,G$3) -> 0 | H28: =$P28*MIN($Q28,H$3) -> 0 | I28: =$P28*MIN($Q28,I$3) -> 0 | J28: auth_ldap | K28: base.group_user | M28: =INDEX('Pivot Analysis'!A:B,MATCH(J28,'Pivot Analysis'!B:B,0),1) -> 0 | N28: =INDEX(Cloc!E:F,MATCH(J28,Cloc!F:F,0),1) -> #N/A | O28: =IFERROR(IFERROR(IF(L28<>"",L28,M28),N28),$O$1) -> 0 | P28: =O28/Q28 -> 0 | Q28: =MAX(1,SUMPRODUCT($R$1:$AD$1,R28:AD28)) -> 1
A29: =J29&";"&K29&";"&B29&";"&C29&";"&D29&";"&E29&";"&F29&";"&G29&";"&H29&";"&I29 -> auth_oauth;base.group_user;0;0;0;0;0;0;0;0 | B29: =$P29*MIN($Q29,B$3) -> 0 | C29: =$P29*MIN($Q29,C$3) -> 0 | D29: =$P29*MIN($Q29,D$3) -> 0 | E29: =$P29*MIN($Q29,E$3) -> 0 | F29: =$P29*MIN($Q29,F$3) -> 0 | G29: =$P29*MIN($Q29,G$3) -> 0 | H29: =$P29*MIN($Q29,H$3) -> 0 | I29: =$P29*MIN($Q29,I$3) -> 0 | J29: auth_oauth | K29: base.group_user | M29: =INDEX('Pivot Analysis'!A:B,MATCH(J29,'Pivot Analysis'!B:B,0),1) -> 0 | N29: =INDEX(Cloc!E:F,MATCH(J29,Cloc!F:F,0),1) -> #N/A | O29: =IFERROR(IFERROR(IF(L29<>"",L29,M29),N29),$O$1) -> 0 | P29: =O29/Q29 -> 0 | Q29: =MAX(1,SUMPRODUCT($R$1:$AD$1,R29:AD29)) -> 1
A30: =J30&";"&K30&";"&B30&";"&C30&";"&D30&";"&E30&";"&F30&";"&G30&";"&H30&";"&I30 -> auth_passkey;base.group_user;1000;1000;1000;1000;1000;1000;1000;1000 | B30: =$P30*MIN($Q30,B$3) -> 1000 | C30: =$P30*MIN($Q30,C$3) -> 1000 | D30: =$P30*MIN($Q30,D$3) -> 1000 | E30: =$P30*MIN($Q30,E$3) -> 1000 | F30: =$P30*MIN($Q30,F$3) -> 1000 | G30: =$P30*MIN($Q30,G$3) -> 1000 | H30: =$P30*MIN($Q30,H$3) -> 1000 | I30: =$P30*MIN($Q30,I$3) -> 1000 | J30: auth_passkey | K30: base.group_user | M30: =INDEX('Pivot Analysis'!A:B,MATCH(J30,'Pivot Analysis'!B:B,0),1) -> #N/A | N30: =INDEX(Cloc!E:F,MATCH(J30,Cloc!F:F,0),1) -> #N/A | O30: =IFERROR(IFERROR(IF(L30<>"",L30,M30),N30),$O$1) -> 1000 | P30: =O30/Q30 -> 1000 | Q30: =MAX(1,SUMPRODUCT($R$1:$AD$1,R30:AD30)) -> 1 | Z30: 1
A31: =J31&";"&K31&";"&B31&";"&C31&";"&D31&";"&E31&";"&F31&";"&G31&";"&H31&";"&I31 -> auth_password_policy;base.group_user;3;3;3;3;3;3;3;3 | B31: =$P31*MIN($Q31,B$3) -> 3 | C31: =$P31*MIN($Q31,C$3) -> 3 | D31: =$P31*MIN($Q31,D$3) -> 3 | E31: =$P31*MIN($Q31,E$3) -> 3 | F31: =$P31*MIN($Q31,F$3) -> 3 | G31: =$P31*MIN($Q31,G$3) -> 3 | H31: =$P31*MIN($Q31,H$3) -> 3 | I31: =$P31*MIN($Q31,I$3) -> 3 | J31: auth_password_policy | K31: base.group_user | M31: =INDEX('Pivot Analysis'!A:B,MATCH(J31,'Pivot Analysis'!B:B,0),1) -> 3 | N31: =INDEX(Cloc!E:F,MATCH(J31,Cloc!F:F,0),1) -> #N/A | O31: =IFERROR(IFERROR(IF(L31<>"",L31,M31),N31),$O$1) -> 3 | P31: =O31/Q31 -> 3 | Q31: =MAX(1,SUMPRODUCT($R$1:$AD$1,R31:AD31)) -> 1
A32: =J32&";"&K32&";"&B32&";"&C32&";"&D32&";"&E32&";"&F32&";"&G32&";"&H32&";"&I32 -> auth_password_policy_portal;base.group_user;33;33;33;33;33;33;33;33 | B32: =$P32*MIN($Q32,B$3) -> 33 | C32: =$P32*MIN($Q32,C$3) -> 33 | D32: =$P32*MIN($Q32,D$3) -> 33 | E32: =$P32*MIN($Q32,E$3) -> 33 | F32: =$P32*MIN($Q32,F$3) -> 33 | G32: =$P32*MIN($Q32,G$3) -> 33 | H32: =$P32*MIN($Q32,H$3) -> 33 | I32: =$P32*MIN($Q32,I$3) -> 33 | J32: auth_password_policy_portal | K32: base.group_user | M32: =INDEX('Pivot Analysis'!A:B,MATCH(J32,'Pivot Analysis'!B:B,0),1) -> 33 | N32: =INDEX(Cloc!E:F,MATCH(J32,Cloc!F:F,0),1) -> #N/A | O32: =IFERROR(IFERROR(IF(L32<>"",L32,M32),N32),$O$1) -> 33 | P32: =O32/Q32 -> 33 | Q32: =MAX(1,SUMPRODUCT($R$1:$AD$1,R32:AD32)) -> 1
A33: =J33&";"&K33&";"&B33&";"&C33&";"&D33&";"&E33&";"&F33&";"&G33&";"&H33&";"&I33 -> auth_password_policy_signup;base.group_user;3;3;3;3;3;3;3;3 | B33: =$P33*MIN($Q33,B$3) -> 3 | C33: =$P33*MIN($Q33,C$3) -> 3 | D33: =$P33*MIN($Q33,D$3) -> 3 | E33: =$P33*MIN($Q33,E$3) -> 3 | F33: =$P33*MIN($Q33,F$3) -> 3 | G33: =$P33*MIN($Q33,G$3) -> 3 | H33: =$P33*MIN($Q33,H$3) -> 3 | I33: =$P33*MIN($Q33,I$3) -> 3 | J33: auth_password_policy_signup | K33: base.group_user | M33: =INDEX('Pivot Analysis'!A:B,MATCH(J33,'Pivot Analysis'!B:B,0),1) -> 3 | N33: =INDEX(Cloc!E:F,MATCH(J33,Cloc!F:F,0),1) -> #N/A | O33: =IFERROR(IFERROR(IF(L33<>"",L33,M33),N33),$O$1) -> 3 | P33: =O33/Q33 -> 3 | Q33: =MAX(1,SUMPRODUCT($R$1:$AD$1,R33:AD33)) -> 1
A34: =J34&";"&K34&";"&B34&";"&C34&";"&D34&";"&E34&";"&F34&";"&G34&";"&H34&";"&I34 -> auth_signup;base.group_user;0;0;0;0;0;0;0;0 | B34: =$P34*MIN($Q34,B$3) -> 0 | C34: =$P34*MIN($Q34,C$3) -> 0 | D34: =$P34*MIN($Q34,D$3) -> 0 | E34: =$P34*MIN($Q34,E$3) -> 0 | F34: =$P34*MIN($Q34,F$3) -> 0 | G34: =$P34*MIN($Q34,G$3) -> 0 | H34: =$P34*MIN($Q34,H$3) -> 0 | I34: =$P34*MIN($Q34,I$3) -> 0 | J34: auth_signup | K34: base.group_user | M34: =INDEX('Pivot Analysis'!A:B,MATCH(J34,'Pivot Analysis'!B:B,0),1) -> 0 | N34: =INDEX(Cloc!E:F,MATCH(J34,Cloc!F:F,0),1) -> 87.3 | O34: =IFERROR(IFERROR(IF(L34<>"",L34,M34),N34),$O$1) -> 0 | P34: =O34/Q34 -> 0 | Q34: =MAX(1,SUMPRODUCT($R$1:$AD$1,R34:AD34)) -> 10 | T34: 1 | X34: =IF(SUM(R34:W34)=0,VLOOKUP(J34,#REF!,1,0),"") | Y34: =IF(SUM(R34:X34)>0,"",VLOOKUP(J34,'Apps-from-odoo'!A:A,1,0))
A35: =J35&";"&K35&";"&B35&";"&C35&";"&D35&";"&E35&";"&F35&";"&G35&";"&H35&";"&I35 -> auth_totp;base.group_user;0;0;0;0;0;0;0;0 | B35: =$P35*MIN($Q35,B$3) -> 0 | C35: =$P35*MIN($Q35,C$3) -> 0 | D35: =$P35*MIN($Q35,D$3) -> 0 | E35: =$P35*MIN($Q35,E$3) -> 0 | F35: =$P35*MIN($Q35,F$3) -> 0 | G35: =$P35*MIN($Q35,G$3) -> 0 | H35: =$P35*MIN($Q35,H$3) -> 0 | I35: =$P35*MIN($Q35,I$3) -> 0 | J35: auth_totp | K35: base.group_user | M35: =INDEX('Pivot Analysis'!A:B,MATCH(J35,'Pivot Analysis'!B:B,0),1) -> 0 | N35: =INDEX(Cloc!E:F,MATCH(J35,Cloc!F:F,0),1) -> 43.86 | O35: =IFERROR(IFERROR(IF(L35<>"",L35,M35),N35),$O$1) -> 0 | P35: =O35/Q35 -> 0 | Q35: =MAX(1,SUMPRODUCT($R$1:$AD$1,R35:AD35)) -> 1000 | R35: 1 | X35: =IF(SUM(R35:W35)=0,VLOOKUP(J35,#REF!,1,0),"") | Y35: =IF(SUM(R35:X35)>0,"",VLOOKUP(J35,'Apps-from-odoo'!A:A,1,0))
A36: =J36&";"&K36&";"&B36&";"&C36&";"&D36&";"&E36&";"&F36&";"&G36&";"&H36&";"&I36 -> auth_totp_mail;base.group_user;0,3;0,6;0,9;1,2;1,5;1,8;2,1;2,4 | B36: =$P36*MIN($Q36,B$3) -> 0.3 | C36: =$P36*MIN($Q36,C$3) -> 0.6 | D36: =$P36*MIN($Q36,D$3) -> 0.9 | E36: =$P36*MIN($Q36,E$3) -> 1.2 | F36: =$P36*MIN($Q36,F$3) -> 1.5 | G36: =$P36*MIN($Q36,G$3) -> 1.8 | H36: =$P36*MIN($Q36,H$3) -> 2.1 | I36: =$P36*MIN($Q36,I$3) -> 2.4 | J36: auth_totp_mail | K36: base.group_user | M36: =INDEX('Pivot Analysis'!A:B,MATCH(J36,'Pivot Analysis'!B:B,0),1) -> 3 | N36: =INDEX(Cloc!E:F,MATCH(J36,Cloc!F:F,0),1) -> 15.06 | O36: =IFERROR(IFERROR(IF(L36<>"",L36,M36),N36),$O$1) -> 3 | P36: =O36/Q36 -> 0.3 | Q36: =MAX(1,SUMPRODUCT($R$1:$AD$1,R36:AD36)) -> 10 | T36: 1 | X36: =IF(SUM(R36:W36)=0,VLOOKUP(J36,#REF!,1,0),"") | Y36: =IF(SUM(R36:X36)>0,"",VLOOKUP(J36,'Apps-from-odoo'!A:A,1,0))
A37: =J37&";"&K37&";"&B37&";"&C37&";"&D37&";"&E37&";"&F37&";"&G37&";"&H37&";"&I37 -> auth_totp_mail_enforce;base.group_user;0;0;0;0;0;0;0;0 | B37: =$P37*MIN($Q37,B$3) -> 0 | C37: =$P37*MIN($Q37,C$3) -> 0 | D37: =$P37*MIN($Q37,D$3) -> 0 | E37: =$P37*MIN($Q37,E$3) -> 0 | F37: =$P37*MIN($Q37,F$3) -> 0 | G37: =$P37*MIN($Q37,G$3) -> 0 | H37: =$P37*MIN($Q37,H$3) -> 0 | I37: =$P37*MIN($Q37,I$3) -> 0 | J37: auth_totp_mail_enforce | K37: base.group_user | M37: =INDEX('Pivot Analysis'!A:B,MATCH(J37,'Pivot Analysis'!B:B,0),1) -> 0 | N37: =INDEX(Cloc!E:F,MATCH(J37,Cloc!F:F,0),1) -> #N/A | O37: =IFERROR(IFERROR(IF(L37<>"",L37,M37),N37),$O$1) -> 0 | P37: =O37/Q37 -> 0 | Q37: =MAX(1,SUMPRODUCT($R$1:$AD$1,R37:AD37)) -> 1
A38: =J38&";"&K38&";"&B38&";"&C38&";"&D38&";"&E38&";"&F38&";"&G38&";"&H38&";"&I38 -> auth_totp_portal;base.group_user;0,3;0,6;0,9;1,2;1,5;1,8;2,1;2,4 | B38: =$P38*MIN($Q38,B$3) -> 0.3 | C38: =$P38*MIN($Q38,C$3) -> 0.6 | D38: =$P38*MIN($Q38,D$3) -> 0.9 | E38: =$P38*MIN($Q38,E$3) -> 1.2 | F38: =$P38*MIN($Q38,F$3) -> 1.5 | G38: =$P38*MIN($Q38,G$3) -> 1.8 | H38: =$P38*MIN($Q38,H$3) -> 2.1 | I38: =$P38*MIN($Q38,I$3) -> 2.4 | J38: auth_totp_portal | K38: base.group_user | M38: =INDEX('Pivot Analysis'!A:B,MATCH(J38,'Pivot Analysis'!B:B,0),1) -> 3 | N38: =INDEX(Cloc!E:F,MATCH(J38,Cloc!F:F,0),1) -> 24.24 | O38: =IFERROR(IFERROR(IF(L38<>"",L38,M38),N38),$O$1) -> 3 | P38: =O38/Q38 -> 0.3 | Q38: =MAX(1,SUMPRODUCT($R$1:$AD$1,R38:AD38)) -> 10 | U38: 1 | X38: =IF(SUM(R38:W38)=0,VLOOKUP(J38,#REF!,1,0),"") | Y38: =IF(SUM(R38:X38)>0,"",VLOOKUP(J38,'Apps-from-odoo'!A:A,1,0))
A39: =J39&";"&K39&";"&B39&";"&C39&";"&D39&";"&E39&";"&F39&";"&G39&";"&H39&";"&I39 -> barcodes;base.group_user;0;0;0;0;0;0;0;0 | B39: =$P39*MIN($Q39,B$3) -> 0 | C39: =$P39*MIN($Q39,C$3) -> 0 | D39: =$P39*MIN($Q39,D$3) -> 0 | E39: =$P39*MIN($Q39,E$3) -> 0 | F39: =$P39*MIN($Q39,F$3) -> 0 | G39: =$P39*MIN($Q39,G$3) -> 0 | H39: =$P39*MIN($Q39,H$3) -> 0 | I39: =$P39*MIN($Q39,I$3) -> 0 | J39: barcodes | K39: base.group_user | M39: =INDEX('Pivot Analysis'!A:B,MATCH(J39,'Pivot Analysis'!B:B,0),1) -> 0 | N39: =INDEX(Cloc!E:F,MATCH(J39,Cloc!F:F,0),1) -> 68.7 | O39: =IFERROR(IFERROR(IF(L39<>"",L39,M39),N39),$O$1) -> 0 | P39: =O39/Q39 -> 0 | Q39: =MAX(1,SUMPRODUCT($R$1:$AD$1,R39:AD39)) -> 5 | X39: 1 | Y39: =IF(SUM(R39:X39)>0,"",VLOOKUP(J39,'Apps-from-odoo'!A:A,1,0))
A40: =J40&";"&K40&";"&B40&";"&C40&";"&D40&";"&E40&";"&F40&";"&G40&";"&H40&";"&I40 -> barcodes_gs1_nomenclature;base.group_user;0;0;0;0;0;0;0;0 | B40: =$P40*MIN($Q40,B$3) -> 0 | C40: =$P40*MIN($Q40,C$3) -> 0 | D40: =$P40*MIN($Q40,D$3) -> 0 | E40: =$P40*MIN($Q40,E$3) -> 0 | F40: =$P40*MIN($Q40,F$3) -> 0 | G40: =$P40*MIN($Q40,G$3) -> 0 | H40: =$P40*MIN($Q40,H$3) -> 0 | I40: =$P40*MIN($Q40,I$3) -> 0 | J40: barcodes_gs1_nomenclature | K40: base.group_user | M40: =INDEX('Pivot Analysis'!A:B,MATCH(J40,'Pivot Analysis'!B:B,0),1) -> 0 | N40: =INDEX(Cloc!E:F,MATCH(J40,Cloc!F:F,0),1) -> 67.38 | O40: =IFERROR(IFERROR(IF(L40<>"",L40,M40),N40),$O$1) -> 0 | P40: =O40/Q40 -> 0 | Q40: =MAX(1,SUMPRODUCT($R$1:$AD$1,R40:AD40)) -> 5 | X40: 1 | Y40: =IF(SUM(R40:X40)>0,"",VLOOKUP(J40,'Apps-from-odoo'!A:A,1,0))
A41: =J41&";"&K41&";"&B41&";"&C41&";"&D41&";"&E41&";"&F41&";"&G41&";"&H41&";"&I41 -> base;base.group_user;0;0;0;0;0;0;0;0 | B41: =$P41*MIN($Q41,B$3) -> 0 | C41: =$P41*MIN($Q41,C$3) -> 0 | D41: =$P41*MIN($Q41,D$3) -> 0 | E41: =$P41*MIN($Q41,E$3) -> 0 | F41: =$P41*MIN($Q41,F$3) -> 0 | G41: =$P41*MIN($Q41,G$3) -> 0 | H41: =$P41*MIN($Q41,H$3) -> 0 | I41: =$P41*MIN($Q41,I$3) -> 0 | J41: base | K41: base.group_user | M41: =INDEX('Pivot Analysis'!A:B,MATCH(J41,'Pivot Analysis'!B:B,0),1) -> 0 | N41: =INDEX(Cloc!E:F,MATCH(J41,Cloc!F:F,0),1) -> 2431.98 | O41: =IFERROR(IFERROR(IF(L41<>"",L41,M41),N41),$O$1) -> 0 | P41: =O41/Q41 -> 0 | Q41: =MAX(1,SUMPRODUCT($R$1:$AD$1,R41:AD41)) -> 1000 | R41: 1 | X41: =IF(SUM(R41:W41)=0,VLOOKUP(J41,#REF!,1,0),"") | Y41: =IF(SUM(R41:X41)>0,"",VLOOKUP(J41,'Apps-from-odoo'!A:A,1,0))
...

Sheet Apps-from-odoo
A1: Technical Name | B1: Exists in Apps
A2: account | B2: =VLOOKUP(A2,Apps!J:J,1,0) -> account
A3: account_check_printing | B3: =VLOOKUP(A3,Apps!J:J,1,0) -> account_check_printing
A4: account_debit_note | B4: =VLOOKUP(A4,Apps!J:J,1,0) -> account_debit_note
A5: account_edi | B5: =VLOOKUP(A5,Apps!J:J,1,0) -> account_edi
A6: account_edi_proxy_client | B6: =VLOOKUP(A6,Apps!J:J,1,0) -> account_edi_proxy_client
A7: account_edi_ubl_cii | B7: =VLOOKUP(A7,Apps!J:J,1,0) -> account_edi_ubl_cii
A8: account_edi_ubl_cii_tax_extension | B8: =VLOOKUP(A8,Apps!J:J,1,0) -> account_edi_ubl_cii_tax_extension
A9: account_fleet | B9: =VLOOKUP(A9,Apps!J:J,1,0) -> account_fleet
A10: account_payment | B10: =VLOOKUP(A10,Apps!J:J,1,0) -> account_payment
A11: account_peppol | B11: =VLOOKUP(A11,Apps!J:J,1,0) -> account_peppol
A12: account_qr_code_emv | B12: =VLOOKUP(A12,Apps!J:J,1,0) -> account_qr_code_emv
A13: account_qr_code_sepa | B13: =VLOOKUP(A13,Apps!J:J,1,0) -> account_qr_code_sepa
... A627: website_sms | B627: =VLOOKUP(A627,Apps!J:J,1,0) -> website_sms

Sheet Pivot Analysis
B1: Weight (EUR/minute) - not in 16-17 | D1: 3
A2: EUR | B2: Weight (EUR/minute) | C2: 3 | D2: 0.3
A4: EUR | B4: Summer av Minutes | C4: Kolonneetiketter
B5: Radetiketter | C5: 16-17 | D5: 17-18 | E5: Totalsum
A6: =IF(C6="",SUMPRODUCT($C$1:$D$1,$C6:$D6),SUMPRODUCT($C$2:$D$2,$C6:$D6)) -> 240 | B6: account | C6: 0 | D6: 800 | E6: 800
A7: =IF(C7="",SUMPRODUCT($C$1:$D$1,$C7:$D7),SUMPRODUCT($C$2:$D$2,$C7:$D7)) -> 0 | B7: account_audit_trail | D7: 0 | E7: 0
A8: =IF(C8="",SUMPRODUCT($C$1:$D$1,$C8:$D8),SUMPRODUCT($C$2:$D$2,$C8:$D8)) -> 7.5 | B8: account_check_printing | C8: 0 | D8: 25 | E8: 25
A9: =IF(C9="",SUMPRODUCT($C$1:$D$1,$C9:$D9),SUMPRODUCT($C$2:$D$2,$C9:$D9)) -> 34.5 | B9: account_debit_note | C9: 10 | D9: 15 | E9: 25
A10: =IF(C10="",SUMPRODUCT($C$1:$D$1,$C10:$D10),SUMPRODUCT($C$2:$D$2,$C10:$D10)) -> 0 | B10: account_edi | C10: 0 | D10: 0 | E10: 0
A11: =IF(C11="",SUMPRODUCT($C$1:$D$1,$C11:$D11),SUMPRODUCT($C$2:$D$2,$C11:$D11)) -> 81 | B11: account_edi_proxy_client | C11: 25 | D11: 20 | E11: 45
A12: =IF(C12="",SUMPRODUCT($C$1:$D$1,$C12:$D12),SUMPRODUCT($C$2:$D$2,$C12:$D12)) -> 12.3 | B12: account_edi_ubl_cii | C12: 0 | D12: 41 | E12: 41
A13: =IF(C13="",SUMPRODUCT($C$1:$D$1,$C13:$D13),SUMPRODUCT($C$2:$D$2,$C13:$D13)) -> 0 | B13: account_edi_ubl_cii_tax_extension | C13: 0 | D13: 0 | E13: 0
A14: =IF(C14="",SUMPRODUCT($C$1:$D$1,$C14:$D14),SUMPRODUCT($C$2:$D$2,$C14:$D14)) -> 7.5 | B14: account_fleet | C14: 0 | D14: 25 | E14: 25
A15: =IF(C15="",SUMPRODUCT($C$1:$D$1,$C15:$D15),SUMPRODUCT($C$2:$D$2,$C15:$D15)) -> 30 | B15: account_lock | C15: 10 | D15: 0 | E15: 10
A16: =IF(C16="",SUMPRODUCT($C$1:$D$1,$C16:$D16),SUMPRODUCT($C$2:$D$2,$C16:$D16)) -> 3.3 | B16: account_payment | C16: 0 | D16: 11 | E16: 11
A17: =IF(C17="",SUMPRODUCT($C$1:$D$1,$C17:$D17),SUMPRODUCT($C$2:$D$2,$C17:$D17)) -> 0 | B17: account_payment_invoice_online_payment_patch | C17: 0 | E17: 0
A18: =IF(C18="",SUMPRODUCT($C$1:$D$1,$C18:$D18),SUMPRODUCT($C$2:$D$2,$C18:$D18)) -> 0 | B18: account_payment_term | D18: 0 | E18: 0
A19: =IF(C19="",SUMPRODUCT($C$1:$D$1,$C19:$D19),SUMPRODUCT($C$2:$D$2,$C19:$D19)) -> 258 | B19: account_peppol | D19: 86 | E19: 86
A20: =IF(C20="",SUMPRODUCT($C$1:$D$1,$C20:$D20),SUMPRODUCT($C$2:$D$2,$C20:$D20)) -> 45 | B20: account_qr_code_emv | D20: 15 | E20: 15
A21: =IF(C21="",SUMPRODUCT($C$1:$D$1,$C21:$D21),SUMPRODUCT($C$2:$D$2,$C21:$D21)) -> 3 | B21: account_qr_code_sepa | C21: 0 | D21: 10 | E21: 10
A22: =IF(C22="",SUMPRODUCT($C$1:$D$1,$C22:$D22),SUMPRODUCT($C$2:$D$2,$C22:$D22)) -> 0 | B22: account_sequence | C22: 0 | E22: 0
A23: =IF(C23="",SUMPRODUCT($C$1:$D$1,$C23:$D23),SUMPRODUCT($C$2:$D$2,$C23:$D23)) -> 82.5 | B23: account_tax_python | C23: 25 | D23: 25 | E23: 50
A24: =IF(C24="",SUMPRODUCT($C$1:$D$1,$C24:$D24),SUMPRODUCT($C$2:$D$2,$C24:$D24)) -> 33 | B24: account_test | C24: 10 | D24: 10 | E24: 20
A25: =IF(C25="",SUMPRODUCT($C$1:$D$1,$C25:$D25),SUMPRODUCT($C$2:$D$2,$C25:$D25)) -> 0 | B25: account_update_tax_tags | C25: 0 | D25: 0 | E25: 0
A26: =IF(C26="",SUMPRODUCT($C$1:$D$1,$C26:$D26),SUMPRODUCT($C$2:$D$2,$C26:$D26)) -> 0 | B26: analytic | C26: 0 | D26: 0 | E26: 0
A27: =IF(C27="",SUMPRODUCT($C$1:$D$1,$C27:$D27),SUMPRODUCT($C$2:$D$2,$C27:$D27)) -> 0 | B27: association | C27: 0 | E27: 0
A28: =IF(C28="",SUMPRODUCT($C$1:$D$1,$C28:$D28),SUMPRODUCT($C$2:$D$2,$C28:$D28)) -> 3 | B28: attachment_indexation | C28: 0 | D28: 10 | E28: 10
A29: =IF(C29="",SUMPRODUCT($C$1:$D$1,$C29:$D29),SUMPRODUCT($C$2:$D$2,$C29:$D29)) -> 0 | B29: auth_ldap | C29: 0 | D29: 0 | E29: 0
A30: =IF(C30="",SUMPRODUCT($C$1:$D$1,$C30:$D30),SUMPRODUCT($C$2:$D$2,$C30:$D30)) -> 0 | B30: auth_oauth | C30: 0 | D30: 0 | E30: 0
A31: =IF(C31="",SUMPRODUCT($C$1:$D$1,$C31:$D31),SUMPRODUCT($C$2:$D$2,$C31:$D31)) -> 3 | B31: auth_password_policy | C31: 0 | D31: 10 | E31: 10
A32: =IF(C32="",SUMPRODUCT($C$1:$D$1,$C32:$D32),SUMPRODUCT($C$2:$D$2,$C32:$D32)) -> 33 | B32: auth_password_policy_portal | C32: 10 | D32: 10 | E32: 20
A33: =IF(C33="",SUMPRODUCT($C$1:$D$1,$C33:$D33),SUMPRODUCT($C$2:$D$2,$C33:$D33)) -> 3 | B33: auth_password_policy_signup | C33: 0 | D33: 10 | E33: 10
A34: =IF(C34="",SUMPRODUCT($C$1:$D$1,$C34:$D34),SUMPRODUCT($C$2:$D$2,$C34:$D34)) -> 0 | B34: auth_signup | C34: 0 | D34: 0 | E34: 0
A35: =IF(C35="",SUMPRODUCT($C$1:$D$1,$C35:$D35),SUMPRODUCT($C$2:$D$2,$C35:$D35)) -> 0 | B35: auth_totp | C35: 0 | D35: 0 | E35: 0
A36: =IF(C36="",SUMPRODUCT($C$1:$D$1,$C36:$D36),SUMPRODUCT($C$2:$D$2,$C36:$D36)) -> 3 | B36: auth_totp_mail | C36: 0 | D36: 10 | E36: 10
A37: =IF(C37="",SUMPRODUCT($C$1:$D$1,$C37:$D37),SUMPRODUCT($C$2:$D$2,$C37:$D37)) -> 0 | B37: auth_totp_mail_enforce | C37: 0 | D37: 0 | E37: 0
A38: =IF(C38="",SUMPRODUCT($C$1:$D$1,$C38:$D38),SUMPRODUCT($C$2:$D$2,$C38:$D38)) -> 3 | B38: auth_totp_portal | C38: 0 | D38: 10 | E38: 10
A39: =IF(C39="",SUMPRODUCT($C$1:$D$1,$C39:$D39),SUMPRODUCT($C$2:$D$2,$C39:$D39)) -> 0 | B39: barcodes | C39: 0 | D39: 0 | E39: 0
A40: =IF(C40="",SUMPRODUCT($C$1:$D$1,$C40:$D40),SUMPRODUCT($C$2:$D$2,$C40:$D40)) -> 0 | B40: barcodes_gs1_nomenclature | C40: 0 | D40: 0 | E40: 0
A41: =IF(C41="",SUMPRODUCT($C$1:$D$1,$C41:$D41),SUMPRODUCT($C$2:$D$2,$C41:$D41)) -> 0 | B41: base | D41: 0 | E41: 0
...

Sheet Analysis
A1: Mig | B1: Minutes | C1: App | D1: Hours
A2: 16-17 | B2: =D2*24*60 -> 0 | C2: account | E2: None | F2: Done
A3: 16-17 | B3: =D3*24*60 -> 0 | F3: (Model: 11, Field: 269, XML: 134)
A4: 16-17 | B4: =D4*24*60 -> 0 | C4: account_check_printing | E4: None | F4: Nothing to do No DB layout changes.
A5: 16-17 | B5: =D5*24*60 -> 10 | C5: account_debit_note | D5: 0.0069444444 | E5: None | F5: To analyse(0:10)
A6: 16-17 | B6: =D6*24*60 -> 0 | F6: (XML: 1)
A7: 16-17 | B7: =D7*24*60 -> 0 | C7: account_edi | E7: None | F7: Done
A8: 16-17 | B8: =D8*24*60 -> 0 | F8: (XML: 2)
A9: 16-17 | B9: =D9*24*60 -> 25 | C9: account_edi_proxy_client | D9: 0.017361111 | E9: None | F9: To analyse(0:25)
A10: 16-17 | B10: =D10*24*60 -> 0 | F10: (Field: 3, XML: 3)
A11: 16-17 | B11: =D11*24*60 -> 0 | C11: account_edi_ubl_cii | E11: None | F11: Done
A12: 16-17 | B12: =D12*24*60 -> 0 | F12: (Field: 5, XML: 32)
A13: 16-17 | B13: =D13*24*60 -> 0 | C13: account_edi_ubl_cii_tax_extension | E13: None | F13: No DB layout changes.
A14: 16-17 | B14: =D14*24*60 -> 0 | C14: account_fleet | E14: None | F14: No DB layout changes.
A15: 16-17 | B15: =D15*24*60 -> 10 | C15: account_lock | D15: 0.0069444444 | E15: None | F15: To analyse(0:10)
A16: 16-17 | B16: =D16*24*60 -> 0 | C16: account_payment | E16: None | F16: Done
A17: 16-17 | B17: =D17*24*60 -> 0 | F17: (XML: 13)
A18: 16-17 | B18: =D18*24*60 -> 0 | C18: account_payment_invoice_online_payment_patch | E18: None | F18: Merged into account_payment
A19: 16-17 | B19: =D19*24*60 -> 0 | C19: account_qr_code_sepa | E19: None | F19: Nothing to do
A20: 16-17 | B20: =D20*24*60 -> 0 | C20: account_sequence | E20: None | F20: Merged into account
A21: 16-17 | B21: =D21*24*60 -> 25 | C21: account_tax_python | D21: 0.017361111 | E21: None | F21: To analyse(0:25)
A22: 16-17 | B22: =D22*24*60 -> 0 | F22: (Field: 3)
A23: 16-17 | B23: =D23*24*60 -> 10 | C23: account_test | D23: 0.0069444444 | E23: None | F23: To analyse(0:10)
A24: 16-17 | B24: =D24*24*60 -> 0 | C24: account_update_tax_tags | E24: None | F24: No DB layout changes.
A25: 16-17 | B25: =D25*24*60 -> 0 | C25: analytic | E25: None | F25: Done
A26: 16-17 | B26: =D26*24*60 -> 0 | F26: (Field: 9, XML: 3)
A27: 16-17 | B27: =D27*24*60 -> 0 | C27: association | E27: None | F27: Merged into membership
A28: 16-17 | B28: =D28*24*60 -> 0 | C28: attachment_indexation | E28: None | F28: Nothing to do
A29: 16-17 | B29: =D29*24*60 -> 0 | C29: auth_ldap | E29: None | F29: No DB layout changes.
A30: 16-17 | B30: =D30*24*60 -> 0 | C30: auth_oauth | E30: None | F30: Nothing to do No DB layout changes.
A31: 16-17 | B31: =D31*24*60 -> 0 | C31: auth_password_policy | E31: None | F31: Nothing to do
A32: 16-17 | B32: =D32*24*60 -> 10 | C32: auth_password_policy_portal | D32: 0.0069444444 | E32: None | F32: To analyse(0:10)
A33: 16-17 | B33: =D33*24*60 -> 0 | C33: auth_password_policy_signup | E33: None | F33: Nothing to do
A34: 16-17 | B34: =D34*24*60 -> 0 | C34: auth_signup | E34: None | F34: Done
A35: 16-17 | B35: =D35*24*60 -> 0 | F35: (XML: 3)
A36: 16-17 | B36: =D36*24*60 -> 0 | C36: auth_totp | E36: None | F36: Nothing to do No DB layout changes.
A37: 16-17 | B37: =D37*24*60 -> 0 | C37: auth_totp_mail | E37: None | F37: Nothing to do
A38: 16-17 | B38: =D38*24*60 -> 0 | F38: (XML: 1)
A39: 16-17 | B39: =D39*24*60 -> 0 | C39: auth_totp_mail_enforce | E39: None | F39: No DB layout changes.
A40: 16-17 | B40: =D40*24*60 -> 0 | C40: auth_totp_portal | E40: None | F40: Nothing to do
...

Sheet Cloc
F1: python odoo-bin cloc -c ../odoo.conf -d o18-mini2
F2: Python
F3: import re
F5: def add_line_breaks(text):
F6: """
F7: Add a line break between numbers and letters in the given text.
F8: """
F9: return re.sub(r'(\d)([a-zA-Z])', r'\1\n\2', text)
F11: def convert_to_csv(output_text):
F12: """
F13: Convert each line of the output text to CSV format.
F14: """
... F27: print(csv_output)
C29: 50 | D29: 50 | E29: 3 | F29: Data - Text to Columns
C31: Minutes | D31: Minutes | E31: EUR | F31: Odoo cloc | G31: Line | H31: Other | I31: Code
C32: =IFERROR(IF(VLOOKUP(F32,'Pivot Analysis'!B:B,1,0)=F32,"",""),G32/$C$29) | D32: =G32/$D$29 -> 996.12 | E32: =D32*$E$29 -> 2988.36 | F32: account | G32: 49806 | H32: 13020 | I32: 36786
C33: =IFERROR(IF(VLOOKUP(F33,'Pivot Analysis'!B:B,1,0)=F33,"",""),G33/$C$29) | D33: =G33/$D$29 -> 94.7 | E33: =D33*$E$29 -> 284.1 | F33: account_edi_ubl_cii | G33: 4735 | H33: 1302 | I33: 3433
C34: =IFERROR(IF(VLOOKUP(F34,'Pivot Analysis'!B:B,1,0)=F34,"",""),G34/$C$29) | D34: =G34/$D$29 -> 5.76 | E34: =D34*$E$29 -> 17.28 | F34: account_fleet | G34: 288 | H34: 56 | I34: 232
C35: =IFERROR(IF(VLOOKUP(F35,'Pivot Analysis'!B:B,1,0)=F35,"",""),G35/$C$29) | D35: =G35/$D$29 -> 46.98 | E35: =D35*$E$29 -> 140.94 | F35: account_payment | G35: 2349 | H35: 585 | I35: 1764
C36: =IFERROR(IF(VLOOKUP(F36,'Pivot Analysis'!B:B,1,0)=F36,"",""),G36/$C$29) | D36: =G36/$D$29 -> 50 | E36: =D36*$E$29 -> 150 | F36: analytic | G36: 2500 | H36: 464 | I36: 2036
C37: =IFERROR(IF(VLOOKUP(F37,'Pivot Analysis'!B:B,1,0)=F37,"",""),G37/$C$29) | D37: =G37/$D$29 -> 3.1 | E37: =D37*$E$29 -> 9.3 | F37: attachment_indexation | G37: 155 | H37: 31 | I37: 124
C38: =IFERROR(IF(VLOOKUP(F38,'Pivot Analysis'!B:B,1,0)=F38,"",""),G38/$C$29) | D38: =G38/$D$29 -> 29.1 | E38: =D38*$E$29 -> 87.3 | F38: auth_signup | G38: 1455 | H38: 285 | I38: 1170
C39: =IFERROR(IF(VLOOKUP(F39,'Pivot Analysis'!B:B,1,0)=F39,"",""),G39/$C$29) | D39: =G39/$D$29 -> 14.62 | E39: =D39*$E$29 -> 43.86 | F39: auth_totp | G39: 731 | H39: 152 | I39: 579
C40: =IFERROR(IF(VLOOKUP(F40,'Pivot Analysis'!B:B,1,0)=F40,"",""),G40/$C$29) | D40: =G40/$D$29 -> 5.02 | E40: =D40*$E$29 -> 15.06 | F40: auth_totp_mail | G40: 251 | H40: 58 | I40: 193
C41: =IFERROR(IF(VLOOKUP(F41,'Pivot Analysis'!B:B,1,0)=F41,"",""),G41/$C$29) | D41: =G41/$D$29 -> 8.08 | E41: =D41*$E$29 -> 24.24 | F41: auth_totp_portal | G41: 404 | H41: 76 | I41: 328
C42: =IFERROR(IF(VLOOKUP(F42,'Pivot Analysis'!B:B,1,0)=F42,"",""),G42/$C$29) | D42: =G42/$D$29 -> 22.9 | E42: =D42*$E$29 -> 68.7 | F42: barcodes | G42: 1145 | H42: 273 | I42: 872
C43: =IFERROR(IF(VLOOKUP(F43,'Pivot Analysis'!B:B,1,0)=F43,"",""),G43/$C$29) | D43: =G43/$D$29 -> 22.46 | E43: =D43*$E$29 -> 67.38 | F43: barcodes_gs1_nomenclature | G43: 1123 | H43: 193 | I43: 930
... C230: =IFERROR(IF(VLOOKUP(F230,'Pivot Analysis'!B:B,1,0)=F230,"",""),G230/$C$29) | D230: =G230/$D$29 -> 1.96 | E230: =D230*$E$29 -> 5.88 | F230: website_sms | G230: 98 | H230: 21 | I230: 77
